<?xml version="1.0" encoding="UTF-8"?>
<testng-results ignored="0" total="6" passed="2" failed="4" skipped="0">
  <reporter-output>
  </reporter-output>
  <suite started-at="2018-11-28T07:53:22Z" name="Default suite" finished-at="2018-11-28T07:53:22Z" duration-ms="90">
    <groups>
    </groups>
    <test started-at="2018-11-28T07:53:22Z" name="Default test" finished-at="2018-11-28T07:53:22Z" duration-ms="90">
      <class name="triangle_test.Test_getSquareOfTriangle">
        <test-method signature="test_SquareOverflow()[pri:0, instance:triangle_test.Test_getSquareOfTriangle@1e66f1f5]" started-at="2018-11-28T10:53:22Z" name="test_SquareOverflow" finished-at="2018-11-28T10:53:22Z" duration-ms="20" status="FAIL">
          <exception class="org.testng.TestException">
            <message>
              <![CDATA[
Method Test_getSquareOfTriangle.test_SquareOverflow()[pri:0, instance:triangle_test.Test_getSquareOfTriangle@1e66f1f5] should have thrown an exception of type class java.lang.Exception]]>
            </message>
            <full-stacktrace>
              <![CDATA[org.testng.TestException: 
Method Test_getSquareOfTriangle.test_SquareOverflow()[pri:0, instance:triangle_test.Test_getSquareOfTriangle@1e66f1f5] should have thrown an exception of type class java.lang.Exception
	at org.testng.internal.ExpectedExceptionsHolder.noException(ExpectedExceptionsHolder.java:89)
	at org.testng.internal.Invoker.handleInvocationResults(Invoker.java:1416)
	at org.testng.internal.Invoker.invokeMethod(Invoker.java:695)
	at org.testng.internal.Invoker.invokeTestMethod(Invoker.java:869)
	at org.testng.internal.Invoker.invokeTestMethods(Invoker.java:1193)
	at org.testng.internal.TestMethodWorker.invokeTestMethods(TestMethodWorker.java:126)
	at org.testng.internal.TestMethodWorker.run(TestMethodWorker.java:109)
	at org.testng.TestRunner.privateRun(TestRunner.java:744)
	at org.testng.TestRunner.run(TestRunner.java:602)
	at org.testng.SuiteRunner.runTest(SuiteRunner.java:380)
	at org.testng.SuiteRunner.runSequentially(SuiteRunner.java:375)
	at org.testng.SuiteRunner.privateRun(SuiteRunner.java:340)
	at org.testng.SuiteRunner.run(SuiteRunner.java:289)
	at org.testng.SuiteRunnerWorker.runSuite(SuiteRunnerWorker.java:52)
	at org.testng.SuiteRunnerWorker.run(SuiteRunnerWorker.java:86)
	at org.testng.TestNG.runSuitesSequentially(TestNG.java:1301)
	at org.testng.TestNG.runSuitesLocally(TestNG.java:1226)
	at org.testng.TestNG.runSuites(TestNG.java:1144)
	at org.testng.TestNG.run(TestNG.java:1115)
	at org.testng.remote.AbstractRemoteTestNG.run(AbstractRemoteTestNG.java:114)
	at org.testng.remote.RemoteTestNG.initAndRun(RemoteTestNG.java:251)
	at org.testng.remote.RemoteTestNG.main(RemoteTestNG.java:77)
]]>
            </full-stacktrace>
          </exception> <!-- org.testng.TestException -->
          <reporter-output>
          </reporter-output>
        </test-method> <!-- test_SquareOverflow -->
        <test-method signature="test_getSquare()[pri:0, instance:triangle_test.Test_getSquareOfTriangle@1e66f1f5]" started-at="2018-11-28T10:53:22Z" name="test_getSquare" finished-at="2018-11-28T10:53:22Z" duration-ms="0" status="PASS">
          <reporter-output>
          </reporter-output>
        </test-method> <!-- test_getSquare -->
        <test-method signature="test_getSquareCantExist()[pri:0, instance:triangle_test.Test_getSquareOfTriangle@1e66f1f5]" started-at="2018-11-28T10:53:22Z" name="test_getSquareCantExist" finished-at="2018-11-28T10:53:22Z" duration-ms="0" status="FAIL">
          <exception class="java.lang.AssertionError">
            <message>
              <![CDATA[expected [NaN] but found [4.0]]]>
            </message>
            <full-stacktrace>
              <![CDATA[java.lang.AssertionError: expected [NaN] but found [4.0]
	at org.testng.Assert.fail(Assert.java:93)
	at org.testng.Assert.failNotEquals(Assert.java:512)
	at org.testng.Assert.assertEquals(Assert.java:221)
	at org.testng.Assert.assertEquals(Assert.java:238)
	at triangle_test.Test_getSquareOfTriangle.test_getSquareCantExist(Test_getSquareOfTriangle.java:34)
	at java.base/jdk.internal.reflect.NativeMethodAccessorImpl.invoke0(Native Method)
	at java.base/jdk.internal.reflect.NativeMethodAccessorImpl.invoke(NativeMethodAccessorImpl.java:62)
	at java.base/jdk.internal.reflect.DelegatingMethodAccessorImpl.invoke(DelegatingMethodAccessorImpl.java:43)
	at java.base/java.lang.reflect.Method.invoke(Method.java:564)
	at org.testng.internal.MethodInvocationHelper.invokeMethod(MethodInvocationHelper.java:108)
	at org.testng.internal.Invoker.invokeMethod(Invoker.java:661)
	at org.testng.internal.Invoker.invokeTestMethod(Invoker.java:869)
	at org.testng.internal.Invoker.invokeTestMethods(Invoker.java:1193)
	at org.testng.internal.TestMethodWorker.invokeTestMethods(TestMethodWorker.java:126)
	at org.testng.internal.TestMethodWorker.run(TestMethodWorker.java:109)
	at org.testng.TestRunner.privateRun(TestRunner.java:744)
	at org.testng.TestRunner.run(TestRunner.java:602)
	at org.testng.SuiteRunner.runTest(SuiteRunner.java:380)
	at org.testng.SuiteRunner.runSequentially(SuiteRunner.java:375)
	at org.testng.SuiteRunner.privateRun(SuiteRunner.java:340)
	at org.testng.SuiteRunner.run(SuiteRunner.java:289)
	at org.testng.SuiteRunnerWorker.runSuite(SuiteRunnerWorker.java:52)
	at org.testng.SuiteRunnerWorker.run(SuiteRunnerWorker.java:86)
	at org.testng.TestNG.runSuitesSequentially(TestNG.java:1301)
	at org.testng.TestNG.runSuitesLocally(TestNG.java:1226)
	at org.testng.TestNG.runSuites(TestNG.java:1144)
	at org.testng.TestNG.run(TestNG.java:1115)
	at org.testng.remote.AbstractRemoteTestNG.run(AbstractRemoteTestNG.java:114)
	at org.testng.remote.RemoteTestNG.initAndRun(RemoteTestNG.java:251)
	at org.testng.remote.RemoteTestNG.main(RemoteTestNG.java:77)
]]>
            </full-stacktrace>
          </exception> <!-- java.lang.AssertionError -->
          <reporter-output>
          </reporter-output>
        </test-method> <!-- test_getSquareCantExist -->
        <test-method signature="test_getSquareNegManual()[pri:0, instance:triangle_test.Test_getSquareOfTriangle@1e66f1f5]" started-at="2018-11-28T10:53:22Z" name="test_getSquareNegManual" finished-at="2018-11-28T10:53:22Z" duration-ms="0" status="FAIL">
          <exception class="java.lang.AssertionError">
            <message>
              <![CDATA[calculates square of triangle with negative side]]>
            </message>
            <full-stacktrace>
              <![CDATA[java.lang.AssertionError: calculates square of triangle with negative side
	at org.testng.Assert.fail(Assert.java:93)
	at triangle_test.Test_getSquareOfTriangle.test_getSquareNegManual(Test_getSquareOfTriangle.java:57)
	at java.base/jdk.internal.reflect.NativeMethodAccessorImpl.invoke0(Native Method)
	at java.base/jdk.internal.reflect.NativeMethodAccessorImpl.invoke(NativeMethodAccessorImpl.java:62)
	at java.base/jdk.internal.reflect.DelegatingMethodAccessorImpl.invoke(DelegatingMethodAccessorImpl.java:43)
	at java.base/java.lang.reflect.Method.invoke(Method.java:564)
	at org.testng.internal.MethodInvocationHelper.invokeMethod(MethodInvocationHelper.java:108)
	at org.testng.internal.Invoker.invokeMethod(Invoker.java:661)
	at org.testng.internal.Invoker.invokeTestMethod(Invoker.java:869)
	at org.testng.internal.Invoker.invokeTestMethods(Invoker.java:1193)
	at org.testng.internal.TestMethodWorker.invokeTestMethods(TestMethodWorker.java:126)
	at org.testng.internal.TestMethodWorker.run(TestMethodWorker.java:109)
	at org.testng.TestRunner.privateRun(TestRunner.java:744)
	at org.testng.TestRunner.run(TestRunner.java:602)
	at org.testng.SuiteRunner.runTest(SuiteRunner.java:380)
	at org.testng.SuiteRunner.runSequentially(SuiteRunner.java:375)
	at org.testng.SuiteRunner.privateRun(SuiteRunner.java:340)
	at org.testng.SuiteRunner.run(SuiteRunner.java:289)
	at org.testng.SuiteRunnerWorker.runSuite(SuiteRunnerWorker.java:52)
	at org.testng.SuiteRunnerWorker.run(SuiteRunnerWorker.java:86)
	at org.testng.TestNG.runSuitesSequentially(TestNG.java:1301)
	at org.testng.TestNG.runSuitesLocally(TestNG.java:1226)
	at org.testng.TestNG.runSuites(TestNG.java:1144)
	at org.testng.TestNG.run(TestNG.java:1115)
	at org.testng.remote.AbstractRemoteTestNG.run(AbstractRemoteTestNG.java:114)
	at org.testng.remote.RemoteTestNG.initAndRun(RemoteTestNG.java:251)
	at org.testng.remote.RemoteTestNG.main(RemoteTestNG.java:77)
]]>
            </full-stacktrace>
          </exception> <!-- java.lang.AssertionError -->
          <reporter-output>
          </reporter-output>
        </test-method> <!-- test_getSquareNegManual -->
        <test-method signature="test_getSquareNegativeSide()[pri:0, instance:triangle_test.Test_getSquareOfTriangle@1e66f1f5]" started-at="2018-11-28T10:53:22Z" name="test_getSquareNegativeSide" finished-at="2018-11-28T10:53:22Z" duration-ms="10" status="FAIL">
          <exception class="org.testng.TestException">
            <message>
              <![CDATA[
Method Test_getSquareOfTriangle.test_getSquareNegativeSide()[pri:0, instance:triangle_test.Test_getSquareOfTriangle@1e66f1f5] should have thrown an exception of type class java.lang.Exception]]>
            </message>
            <full-stacktrace>
              <![CDATA[org.testng.TestException: 
Method Test_getSquareOfTriangle.test_getSquareNegativeSide()[pri:0, instance:triangle_test.Test_getSquareOfTriangle@1e66f1f5] should have thrown an exception of type class java.lang.Exception
	at org.testng.internal.ExpectedExceptionsHolder.noException(ExpectedExceptionsHolder.java:89)
	at org.testng.internal.Invoker.handleInvocationResults(Invoker.java:1416)
	at org.testng.internal.Invoker.invokeMethod(Invoker.java:695)
	at org.testng.internal.Invoker.invokeTestMethod(Invoker.java:869)
	at org.testng.internal.Invoker.invokeTestMethods(Invoker.java:1193)
	at org.testng.internal.TestMethodWorker.invokeTestMethods(TestMethodWorker.java:126)
	at org.testng.internal.TestMethodWorker.run(TestMethodWorker.java:109)
	at org.testng.TestRunner.privateRun(TestRunner.java:744)
	at org.testng.TestRunner.run(TestRunner.java:602)
	at org.testng.SuiteRunner.runTest(SuiteRunner.java:380)
	at org.testng.SuiteRunner.runSequentially(SuiteRunner.java:375)
	at org.testng.SuiteRunner.privateRun(SuiteRunner.java:340)
	at org.testng.SuiteRunner.run(SuiteRunner.java:289)
	at org.testng.SuiteRunnerWorker.runSuite(SuiteRunnerWorker.java:52)
	at org.testng.SuiteRunnerWorker.run(SuiteRunnerWorker.java:86)
	at org.testng.TestNG.runSuitesSequentially(TestNG.java:1301)
	at org.testng.TestNG.runSuitesLocally(TestNG.java:1226)
	at org.testng.TestNG.runSuites(TestNG.java:1144)
	at org.testng.TestNG.run(TestNG.java:1115)
	at org.testng.remote.AbstractRemoteTestNG.run(AbstractRemoteTestNG.java:114)
	at org.testng.remote.RemoteTestNG.initAndRun(RemoteTestNG.java:251)
	at org.testng.remote.RemoteTestNG.main(RemoteTestNG.java:77)
]]>
            </full-stacktrace>
          </exception> <!-- org.testng.TestException -->
          <reporter-output>
          </reporter-output>
        </test-method> <!-- test_getSquareNegativeSide -->
        <test-method signature="test_getSquareRectangTrianAnotherEquation()[pri:0, instance:triangle_test.Test_getSquareOfTriangle@1e66f1f5]" started-at="2018-11-28T10:53:22Z" name="test_getSquareRectangTrianAnotherEquation" finished-at="2018-11-28T10:53:22Z" duration-ms="10" status="PASS">
          <reporter-output>
          </reporter-output>
        </test-method> <!-- test_getSquareRectangTrianAnotherEquation -->
      </class> <!-- triangle_test.Test_getSquareOfTriangle -->
    </test> <!-- Default test -->
  </suite> <!-- Default suite -->
</testng-results>
